ERROR:ex:exception occured
Traceback (most recent call last):
  File "/Users/admin/pyenvs/pyenv4/lib/python3.3/site-packages/mongoengine-0.9.0-py3.3.egg/mongoengine/document.py", line 306, in save
    object_id = collection.save(doc, **write_concern)
  File "/Users/admin/pyenvs/pyenv4/lib/python3.3/site-packages/pymongo-2.8-py3.3-macosx-10.6-x86_64.egg/pymongo/collection.py", line 285, in save
    return self.insert(to_save, manipulate, safe, check_keys, **kwargs)
  File "/Users/admin/pyenvs/pyenv4/lib/python3.3/site-packages/pymongo-2.8-py3.3-macosx-10.6-x86_64.egg/pymongo/collection.py", line 410, in insert
    _check_write_command_response(results)
  File "/Users/admin/pyenvs/pyenv4/lib/python3.3/site-packages/pymongo-2.8-py3.3-macosx-10.6-x86_64.egg/pymongo/helpers.py", line 202, in _check_write_command_response
    raise DuplicateKeyError(error.get("errmsg"), 11000, error)
pymongo.errors.DuplicateKeyError: E11000 duplicate key error index: fivesquare.business.$name_1 dup key: { : "mom" }

During handling of the above exception, another exception occurred:

Traceback (most recent call last):
  File "test.py", line 47, in <module>
    b.save()
  File "/Users/admin/pyenvs/pyenv4/lib/python3.3/site-packages/mongoengine-0.9.0-py3.3.egg/mongoengine/document.py", line 358, in save
    raise NotUniqueError(message % str(err))
mongoengine.errors.NotUniqueError: Tried to save duplicate unique keys (E11000 duplicate key error index: fivesquare.business.$name_1 dup key: { : "mom" })
